Workbook

Sheet README
A1: THE UNLOX ACADEMY - DA/DS TRACK
A2: Excel Minor Project - Sales Operations Analytics
A3: Interview-Grade Data Analytics Assessment · 100 Marks
A5: THE SCENARIO
A6: You have just joined the analytics team at a fast-growing multi-category retailer operating across 6 Indian cities.
A7: The head of sales has handed you 5 raw data files - Orders, Customers, Products, Sales Reps, and Targets - and asked
A8: you to answer a set of business questions before the leadership review tomorrow morning.
A10: The data is REAL-WORLD messy: duplicates, missing references, inconsistent case, invalid records, discontinued SKUs.
A11: Part of the assessment is spotting and handling these issues correctly. A wrong-looking answer isn't always wrong -
A12: sometimes the data itself is telling a story.
A14: RULES OF THE ASSESSMENT
A15: 1. Write your answer in the YELLOW cells on each question sheet. Empty answer cell = 0 marks.
... A22: MARKS DISTRIBUTION
A23: Section | B23: Topic | C23: Questions | D23: Marks
A24: Q1 | B24: Lookup Functions (VLOOKUP, INDEX-MATCH, chained lookups) | C24: 8 | D24: 25
A25: Q2 | B25: Data Cleaning & Quality Diagnostics | C25: 6 | D25: 20
A26: Q3 | B26: Conditional Aggregation (SUMIFS, COUNTIFS, IF logic) | C26: 6 | D26: 25
A27: Q4 | B27: Pivot Tables (2D pivots, % of total, calculated fields) | C27: 5 | D27: 20
A28: Q5 | B28: Advanced (Ranking, Running Totals, Multi-condition) | C28: 5 | D28: 10
B29: TOTAL | C29: 30 | D29: 100
A32: PERFORMANCE TIERS
A33: Marks | B33: Tier | C33: Interview Verdict
A34: 85 - 100 | B34: Excellent | C34: Round 1 clear - Excel not a concern
A35: 70 - 84 | B35: Good | C35: Round 1 clear with minor gaps
A36: 55 - 69 | B36: Borderline | C36: Round 1 uncertain - needs revision
A37: 40 - 54 | B37: Weak | C37: Round 1 likely reject - 2 weeks of practice needed
A38: < 40 | B38: Insufficient | C38: Round 1 reject - foundational gaps
A41: DATA SHEETS OVERVIEW
A42: Sheet | B42: Rows | C42: Key Columns | D42: Joins to
A43: Orders | B43: ~2000 | C43: order_id, order_date, customer_id, product_id, sales_rep_id, quantity, unit_price, discount_pct, final_amount, payment_status, ship_city | D43: All others
A44: Customers | B44: 300 | C44: customer_id (PK), customer_name, age, city, segment, signup_date | D44: Orders via customer_id
A45: Products | B45: 60 | C45: product_id (PK), product_name, category, unit_cost, unit_price, is_active | D45: Orders via product_id
A46: Sales_Reps | B46: 30 | C46: rep_id (PK), rep_name, region, hire_date, team_lead_id | D46: Orders via sales_rep_id, self-join via team_lead_id
A47: Targets | B47: 30 × 12 | C47: rep_id (PK), Jan-24 through Dec-24 monthly target values | D47: Sales_Reps via rep_id

Sheet Orders
A1: order_id | B1: order_date | C1: customer_id | D1: product_id | E1: sales_rep_id | F1: quantity | G1: unit_price | H1: discount_pct | I1: final_amount | J1: payment_status | K1: ship_city | L1: category | M1: region | N1: segment | O1: cust_age | P1: unit_cost | Q1: is_active | R1: profit_margin | S1: id_count | T1: first_dup | U1: cust_exists | V1: blr_grocery_amt
A2: ORD-00001 | B2: 45549 | C2: CUST-0243 | D2: PROD-014 | E2: R007 | F2: 8 | G2: 3620 | H2: 15.4 | I2: 24500.16 | J2: Completed | K2: Pune | L2: =IFERROR(VLOOKUP(D2,Products!A:F,3,0),"") -> Apparel | M2: =IFERROR(VLOOKUP(E2,Sales_Reps!A:E,3,0),"") -> North | N2: =IFERROR(VLOOKUP(C2,Customers!A:F,5,0),"") -> SMB | O2: =IFERROR(VLOOKUP(C2,Customers!A:F,3,0),"") -> 44 | P2: =IFERROR(VLOOKUP(D2,Products!A:F,4,0),"") -> 2509 | Q2: =IFERROR(VLOOKUP(D2,Products!A:F,6,0),"") -> TRUE | R2: =IFERROR((G2-P2)/G2,"") -> 0.30690608 | S2: =COUNTIF($A$2:$A$2001,A2) -> 1 | T2: =IF(AND(S2>1,COUNTIF($A$2:A2,A2)=1),1,0) -> 0 | U2: =COUNTIF(Customers!$A$2:$A$301,C2) -> 1 | V2: =IF(AND(K2="Bengaluru",L2="Grocery"),I2,0) -> 0
A3: ORD-00002 | B3: 45340 | C3: CUST-0202 | D3: PROD-020 | E3: R005 | F3: 2 | G3: 820 | H3: 10.8 | I3: 1462.88 | J3: Pending | K3: Chennai | L3: =IFERROR(VLOOKUP(D3,Products!A:F,3,0),"") -> Apparel | M3: =IFERROR(VLOOKUP(E3,Sales_Reps!A:E,3,0),"") -> North | N3: =IFERROR(VLOOKUP(C3,Customers!A:F,5,0),"") -> Retail | O3: =IFERROR(VLOOKUP(C3,Customers!A:F,3,0),"") -> 39 | P3: =IFERROR(VLOOKUP(D3,Products!A:F,4,0),"") -> 391 | Q3: =IFERROR(VLOOKUP(D3,Products!A:F,6,0),"") -> TRUE | R3: =IFERROR((G3-P3)/G3,"") -> 0.52317073 | S3: =COUNTIF($A$2:$A$2001,A3) -> 1 | T3: =IF(AND(S3>1,COUNTIF($A$2:A3,A3)=1),1,0) -> 0 | U3: =COUNTIF(Customers!$A$2:$A$301,C3) -> 1 | V3: =IF(AND(K3="Bengaluru",L3="Grocery"),I3,0) -> 0
A4: ORD-00003 | B4: 45371 | C4: CUST-0098 | D4: PROD-053 | E4: R014 | F4: 8 | G4: 470 | H4: 3.3 | I4: 3635.92 | J4: Pending | K4: Delhi | L4: =IFERROR(VLOOKUP(D4,Products!A:F,3,0),"") -> Sports | M4: =IFERROR(VLOOKUP(E4,Sales_Reps!A:E,3,0),"") -> South | N4: =IFERROR(VLOOKUP(C4,Customers!A:F,5,0),"") -> Retail | O4: =IFERROR(VLOOKUP(C4,Customers!A:F,3,0),"") -> 52 | P4: =IFERROR(VLOOKUP(D4,Products!A:F,4,0),"") -> 302 | Q4: =IFERROR(VLOOKUP(D4,Products!A:F,6,0),"") -> FALSE | R4: =IFERROR((G4-P4)/G4,"") -> 0.35744681 | S4: =COUNTIF($A$2:$A$2001,A4) -> 1 | T4: =IF(AND(S4>1,COUNTIF($A$2:A4,A4)=1),1,0) -> 0 | U4: =COUNTIF(Customers!$A$2:$A$301,C4) -> 1 | V4: =IF(AND(K4="Bengaluru",L4="Grocery"),I4,0) -> 0
A5: ORD-00004 | B5: 45413 | C5: CUST-0071 | D5: PROD-028 | E5: R006 | F5: 1 | G5: 3660 | H5: 15.7 | I5: 3085.38 | J5: Completed | K5: Delhi | L5: =IFERROR(VLOOKUP(D5,Products!A:F,3,0),"") -> Grocery | M5: =IFERROR(VLOOKUP(E5,Sales_Reps!A:E,3,0),"") -> North | N5: =IFERROR(VLOOKUP(C5,Customers!A:F,5,0),"") -> Corporate | O5: =IFERROR(VLOOKUP(C5,Customers!A:F,3,0),"") -> 46 | P5: =IFERROR(VLOOKUP(D5,Products!A:F,4,0),"") -> 2214 | Q5: =IFERROR(VLOOKUP(D5,Products!A:F,6,0),"") -> FALSE | R5: =IFERROR((G5-P5)/G5,"") -> 0.39508197 | S5: =COUNTIF($A$2:$A$2001,A5) -> 1 | T5: =IF(AND(S5>1,COUNTIF($A$2:A5,A5)=1),1,0) -> 0 | U5: =COUNTIF(Customers!$A$2:$A$301,C5) -> 1 | V5: =IF(AND(K5="Bengaluru",L5="Grocery"),I5,0) -> 0
A6: ORD-00005 | B6: 45611 | C6: CUST-0180 | D6: PROD-012 | E6: R008 | F6: 1 | G6: 3160 | H6: 26 | I6: 2338.4 | J6: Completed | K6: Chennai | L6: =IFERROR(VLOOKUP(D6,Products!A:F,3,0),"") -> Apparel | M6: =IFERROR(VLOOKUP(E6,Sales_Reps!A:E,3,0),"") -> North | N6: =IFERROR(VLOOKUP(C6,Customers!A:F,5,0),"") -> Retail | O6: =IFERROR(VLOOKUP(C6,Customers!A:F,3,0),"") -> 36 | P6: =IFERROR(VLOOKUP(D6,Products!A:F,4,0),"") -> 1886 | Q6: =IFERROR(VLOOKUP(D6,Products!A:F,6,0),"") -> TRUE | R6: =IFERROR((G6-P6)/G6,"") -> 0.40316456 | S6: =COUNTIF($A$2:$A$2001,A6) -> 1 | T6: =IF(AND(S6>1,COUNTIF($A$2:A6,A6)=1),1,0) -> 0 | U6: =COUNTIF(Customers!$A$2:$A$301,C6) -> 1 | V6: =IF(AND(K6="Bengaluru",L6="Grocery"),I6,0) -> 0
A7: ORD-00006 | B7: 45406 | C7: CUST-0275 | D7: PROD-032 | E7: R025 | F7: 4 | G7: 370 | H7: 29 | I7: 1050.8 | J7: Completed | K7: Mumbai | L7: =IFERROR(VLOOKUP(D7,Products!A:F,3,0),"") -> Home | M7: =IFERROR(VLOOKUP(E7,Sales_Reps!A:E,3,0),"") -> West | N7: =IFERROR(VLOOKUP(C7,Customers!A:F,5,0),"") -> Retail | O7: =IFERROR(VLOOKUP(C7,Customers!A:F,3,0),"") -> 36 | P7: =IFERROR(VLOOKUP(D7,Products!A:F,4,0),"") -> 288 | Q7: =IFERROR(VLOOKUP(D7,Products!A:F,6,0),"") -> TRUE | R7: =IFERROR((G7-P7)/G7,"") -> 0.22162162 | S7: =COUNTIF($A$2:$A$2001,A7) -> 1 | T7: =IF(AND(S7>1,COUNTIF($A$2:A7,A7)=1),1,0) -> 0 | U7: =COUNTIF(Customers!$A$2:$A$301,C7) -> 1 | V7: =IF(AND(K7="Bengaluru",L7="Grocery"),I7,0) -> 0
A8: ORD-00007 | B8: 45455 | C8: CUST-0293 | D8: PROD-057 | E8: R024 | F8: 3 | G8: 960 | H8: 5.8 | I8: 2712.96 | J8: Completed | K8: Bengaluru | L8: =IFERROR(VLOOKUP(D8,Products!A:F,3,0),"") -> Sports | M8: =IFERROR(VLOOKUP(E8,Sales_Reps!A:E,3,0),"") -> West | N8: =IFERROR(VLOOKUP(C8,Customers!A:F,5,0),"") -> Retail | O8: =IFERROR(VLOOKUP(C8,Customers!A:F,3,0),"") -> 27 | P8: =IFERROR(VLOOKUP(D8,Products!A:F,4,0),"") -> 705 | Q8: =IFERROR(VLOOKUP(D8,Products!A:F,6,0),"") -> TRUE | R8: =IFERROR((G8-P8)/G8,"") -> 0.265625 | S8: =COUNTIF($A$2:$A$2001,A8) -> 1 | T8: =IF(AND(S8>1,COUNTIF($A$2:A8,A8)=1),1,0) -> 0 | U8: =COUNTIF(Customers!$A$2:$A$301,C8) -> 1 | V8: =IF(AND(K8="Bengaluru",L8="Grocery"),I8,0) -> 0
A9: ORD-00008 | B9: 45617 | C9: CUST-0281 | D9: PROD-007 | E9: R019 | F9: 8 | G9: 1430 | H9: 2.4 | I9: 11165.44 | J9: Completed | K9: Bengaluru | L9: =IFERROR(VLOOKUP(D9,Products!A:F,3,0),"") -> Electronics | M9: =IFERROR(VLOOKUP(E9,Sales_Reps!A:E,3,0),"") -> East | N9: =IFERROR(VLOOKUP(C9,Customers!A:F,5,0),"") -> Corporate | O9: =IFERROR(VLOOKUP(C9,Customers!A:F,3,0),"") -> 57 | P9: =IFERROR(VLOOKUP(D9,Products!A:F,4,0),"") -> 861 | Q9: =IFERROR(VLOOKUP(D9,Products!A:F,6,0),"") -> TRUE | R9: =IFERROR((G9-P9)/G9,"") -> 0.3979021 | S9: =COUNTIF($A$2:$A$2001,A9) -> 1 | T9: =IF(AND(S9>1,COUNTIF($A$2:A9,A9)=1),1,0) -> 0 | U9: =COUNTIF(Customers!$A$2:$A$301,C9) -> 1 | V9: =IF(AND(K9="Bengaluru",L9="Grocery"),I9,0) -> 0
A10: ORD-00009 | B10: 45549 | C10: CUST-0260 | D10: PROD-038 | E10: R008 | F10: 3 | G10: 5490 | H10: 14.2 | I10: 14131.26 | J10: Completed | K10: Bengaluru | L10: =IFERROR(VLOOKUP(D10,Products!A:F,3,0),"") -> Home | M10: =IFERROR(VLOOKUP(E10,Sales_Reps!A:E,3,0),"") -> North | N10: =IFERROR(VLOOKUP(C10,Customers!A:F,5,0),"") -> Retail | O10: =IFERROR(VLOOKUP(C10,Customers!A:F,3,0),"") -> 42 | P10: =IFERROR(VLOOKUP(D10,Products!A:F,4,0),"") -> 2549 | Q10: =IFERROR(VLOOKUP(D10,Products!A:F,6,0),"") -> TRUE | R10: =IFERROR((G10-P10)/G10,"") -> 0.53570128 | S10: =COUNTIF($A$2:$A$2001,A10) -> 1 | T10: =IF(AND(S10>1,COUNTIF($A$2:A10,A10)=1),1,0) -> 0 | U10: =COUNTIF(Customers!$A$2:$A$301,C10) -> 1 | V10: =IF(AND(K10="Bengaluru",L10="Grocery"),I10,0) -> 0
A11: ORD-00010 | B11: 45396 | C11: CUST-0147 | D11: PROD-030 | E11: R028 | F11: 3 | G11: 970 | H11: 1.2 | I11: 2875.08 | J11: Completed | K11: Pune | L11: =IFERROR(VLOOKUP(D11,Products!A:F,3,0),"") -> Grocery | M11: =IFERROR(VLOOKUP(E11,Sales_Reps!A:E,3,0),"") -> West | N11: =IFERROR(VLOOKUP(C11,Customers!A:F,5,0),"") -> Retail | O11: =IFERROR(VLOOKUP(C11,Customers!A:F,3,0),"") -> 56 | P11: =IFERROR(VLOOKUP(D11,Products!A:F,4,0),"") -> 434 | Q11: =IFERROR(VLOOKUP(D11,Products!A:F,6,0),"") -> TRUE | R11: =IFERROR((G11-P11)/G11,"") -> 0.55257732 | S11: =COUNTIF($A$2:$A$2001,A11) -> 1 | T11: =IF(AND(S11>1,COUNTIF($A$2:A11,A11)=1),1,0) -> 0 | U11: =COUNTIF(Customers!$A$2:$A$301,C11) -> 1 | V11: =IF(AND(K11="Bengaluru",L11="Grocery"),I11,0) -> 0
A12: ORD-00011 | B12: 45560 | C12: CUST-0204 | D12: PROD-024 | E12: R010 | F12: 7 | G12: 2270 | H12: 7.1 | I12: 14761.81 | J12: Pending | K12: Hyderabad | L12: =IFERROR(VLOOKUP(D12,Products!A:F,3,0),"") -> Grocery | M12: =IFERROR(VLOOKUP(E12,Sales_Reps!A:E,3,0),"") -> South | N12: =IFERROR(VLOOKUP(C12,Customers!A:F,5,0),"") -> Retail | O12: =IFERROR(VLOOKUP(C12,Customers!A:F,3,0),"") -> 60 | P12: =IFERROR(VLOOKUP(D12,Products!A:F,4,0),"") -> 1203 | Q12: =IFERROR(VLOOKUP(D12,Products!A:F,6,0),"") -> TRUE | R12: =IFERROR((G12-P12)/G12,"") -> 0.47004405 | S12: =COUNTIF($A$2:$A$2001,A12) -> 1 | T12: =IF(AND(S12>1,COUNTIF($A$2:A12,A12)=1),1,0) -> 0 | U12: =COUNTIF(Customers!$A$2:$A$301,C12) -> 1 | V12: =IF(AND(K12="Bengaluru",L12="Grocery"),I12,0) -> 0
A13: ORD-00012 | B13: 45332 | C13: CUST-0147 | D13: PROD-010 | E13: R024 | F13: 9 | G13: 2640 | H13: 21.7 | I13: 18604.08 | J13: Completed | K13: Pune | L13: =IFERROR(VLOOKUP(D13,Products!A:F,3,0),"") -> Electronics | M13: =IFERROR(VLOOKUP(E13,Sales_Reps!A:E,3,0),"") -> West | N13: =IFERROR(VLOOKUP(C13,Customers!A:F,5,0),"") -> Retail | O13: =IFERROR(VLOOKUP(C13,Customers!A:F,3,0),"") -> 56 | P13: =IFERROR(VLOOKUP(D13,Products!A:F,4,0),"") -> 1149 | Q13: =IFERROR(VLOOKUP(D13,Products!A:F,6,0),"") -> TRUE | R13: =IFERROR((G13-P13)/G13,"") -> 0.56477273 | S13: =COUNTIF($A$2:$A$2001,A13) -> 1 | T13: =IF(AND(S13>1,COUNTIF($A$2:A13,A13)=1),1,0) -> 0 | U13: =COUNTIF(Customers!$A$2:$A$301,C13) -> 1 | V13: =IF(AND(K13="Bengaluru",L13="Grocery"),I13,0) -> 0
... A2001: ORD-02000 | B2001: 45325 | C2001: CUST-0238 | D2001: PROD-034 | E2001: R023 | F2001: 6 | G2001: 5080 | H2001: 28.1 | I2001: 21915.12 | J2001: Completed | K2001: Delhi | L2001: =IFERROR(VLOOKUP(D2001,Products!A:F,3,0),"") -> Home | M2001: =IFERROR(VLOOKUP(E2001,Sales_Reps!A:E,3,0),"") -> East | N2001: =IFERROR(VLOOKUP(C2001,Customers!A:F,5,0),"") -> Retail | O2001: =IFERROR(VLOOKUP(C2001,Customers!A:F,3,0),"") -> 49 | P2001: =IFERROR(VLOOKUP(D2001,Products!A:F,4,0),"") -> 2459 | Q2001: =IFERROR(VLOOKUP(D2001,Products!A:F,6,0),"") -> TRUE | R2001: =IFERROR((G2001-P2001)/G2001,"") -> 0.51594488 | S2001: =COUNTIF($A$2:$A$2001,A2001) -> 1 | T2001: =IF(AND(S2001>1,COUNTIF($A$2:A2001,A2001)=1),1,0) -> 0 | U2001: =COUNTIF(Customers!$A$2:$A$301,C2001) -> 1 | V2001: =IF(AND(K2001="Bengaluru",L2001="Grocery"),I2001,0) -> 0

Sheet Customers
A1: customer_id | B1: customer_name | C1: age | D1: city | E1: segment | F1: signup_date | G1: city_upper | H1: first_city | I1: name_len | J1: name_trim_len | K1: has_space
A2: CUST-0001 | B2: Amit Agarwal | C2: 36 | D2: Pune | E2: Retail | F2: 44819 | G2: =UPPER(TRIM(D2)) -> PUNE | H2: =IF(COUNTIF($G$2:G2,G2)=1,1,0) -> 1 | I2: =LEN(B2) -> 12 | J2: =LEN(TRIM(B2)) -> 12 | K2: =IF(I2<>J2,1,0) -> 0
A3: CUST-0002 | B3: Vihaan Malhotra | C3: 42 | D3: Pune | E3: Corporate | F3: 44984 | G3: =UPPER(TRIM(D3)) -> PUNE | H3: =IF(COUNTIF($G$2:G3,G3)=1,1,0) -> 0 | I3: =LEN(B3) -> 15 | J3: =LEN(TRIM(B3)) -> 15 | K3: =IF(I3<>J3,1,0) -> 0
A4: CUST-0003 | B4: Navya Malhotra | C4: 33 | D4: Mumbai | E4: Retail | F4: 44059 | G4: =UPPER(TRIM(D4)) -> MUMBAI | H4: =IF(COUNTIF($G$2:G4,G4)=1,1,0) -> 1 | I4: =LEN(B4) -> 14 | J4: =LEN(TRIM(B4)) -> 14 | K4: =IF(I4<>J4,1,0) -> 0
A5: CUST-0004 | B5: Aaradhya Mehta | C5: 53 | D5: delhi | E5: Retail | F5: 44054 | G5: =UPPER(TRIM(D5)) -> DELHI | H5: =IF(COUNTIF($G$2:G5,G5)=1,1,0) -> 1 | I5: =LEN(B5) -> 14 | J5: =LEN(TRIM(B5)) -> 14 | K5: =IF(I5<>J5,1,0) -> 0
A6: CUST-0005 | B6: Myra Malhotra | C6: 52 | D6: Chennai | E6: Corporate | F6: 45037 | G6: =UPPER(TRIM(D6)) -> CHENNAI | H6: =IF(COUNTIF($G$2:G6,G6)=1,1,0) -> 1 | I6: =LEN(B6) -> 13 | J6: =LEN(TRIM(B6)) -> 13 | K6: =IF(I6<>J6,1,0) -> 0
A7: CUST-0006 | B7: Shaurya Iyer | C7: 44 | D7: Pune | E7: SMB | F7: 44302 | G7: =UPPER(TRIM(D7)) -> PUNE | H7: =IF(COUNTIF($G$2:G7,G7)=1,1,0) -> 0 | I7: =LEN(B7) -> 12 | J7: =LEN(TRIM(B7)) -> 12 | K7: =IF(I7<>J7,1,0) -> 0
A8: CUST-0007 | B8: Dhruv Joshi | C8: 47 | D8: Bengaluru | E8: Retail | F8: 44498 | G8: =UPPER(TRIM(D8)) -> BENGALURU | H8: =IF(COUNTIF($G$2:G8,G8)=1,1,0) -> 1 | I8: =LEN(B8) -> 11 | J8: =LEN(TRIM(B8)) -> 11 | K8: =IF(I8<>J8,1,0) -> 0
A9: CUST-0008 | B9: Kavita Malhotra | C9: 39 | D9: Pune | E9: SMB | F9: 45162 | G9: =UPPER(TRIM(D9)) -> PUNE | H9: =IF(COUNTIF($G$2:G9,G9)=1,1,0) -> 0 | I9: =LEN(B9) -> 15 | J9: =LEN(TRIM(B9)) -> 15 | K9: =IF(I9<>J9,1,0) -> 0
A10: CUST-0009 | B10: Neha Malhotra | C10: 61 | D10: Mumbai | E10: Retail | F10: 44343 | G10: =UPPER(TRIM(D10)) -> MUMBAI | H10: =IF(COUNTIF($G$2:G10,G10)=1,1,0) -> 0 | I10: =LEN(B10) -> 13 | J10: =LEN(TRIM(B10)) -> 13 | K10: =IF(I10<>J10,1,0) -> 0
A11: CUST-0010 | B11: Aaradhya Gupta | C11: 61 | D11: Mumbai | E11: SMB | F11: 44975 | G11: =UPPER(TRIM(D11)) -> MUMBAI | H11: =IF(COUNTIF($G$2:G11,G11)=1,1,0) -> 0 | I11: =LEN(B11) -> 14 | J11: =LEN(TRIM(B11)) -> 14 | K11: =IF(I11<>J11,1,0) -> 0
A12: CUST-0011 | B12: Diya Menon | C12: 41 | D12: Chennai | E12: Corporate | F12: 44821 | G12: =UPPER(TRIM(D12)) -> CHENNAI | H12: =IF(COUNTIF($G$2:G12,G12)=1,1,0) -> 0 | I12: =LEN(B12) -> 10 | J12: =LEN(TRIM(B12)) -> 10 | K12: =IF(I12<>J12,1,0) -> 0
A13: CUST-0012 | B13: Prisha Desai | C13: 43 | D13: Pune | E13: Retail | F13: 44718 | G13: =UPPER(TRIM(D13)) -> PUNE | H13: =IF(COUNTIF($G$2:G13,G13)=1,1,0) -> 0 | I13: =LEN(B13) -> 12 | J13: =LEN(TRIM(B13)) -> 12 | K13: =IF(I13<>J13,1,0) -> 0
... A300: CUST-0299 | B300: Riya Verma | C300: 51 | D300: Mumbai | E300: Corporate | F300: 44675 | G300: =UPPER(TRIM(D300)) -> MUMBAI | H300: =IF(COUNTIF($G$2:G300,G300)=1,1,0) -> 0 | I300: =LEN(B300) -> 10 | J300: =LEN(TRIM(B300)) -> 10 | K300: =IF(I300<>J300,1,0) -> 0
A301: CUST-0300 | B301: Rohit Nair | C301: 38 | D301: Mumbai | E301: Retail | F301: 43932

Sheet Products
A1: product_id | B1: product_name | C1: category | D1: unit_cost | E1: unit_price | F1: is_active | G1: west_revenue | H1: west_rank | I1: product_name_copy
A2: PROD-001 | B2: Smartphone Pro | C2: Electronics | D2: 2405 | E2: 5330 | F2: =TRUE() -> TRUE | G2: =SUMIFS(Orders!$I$2:$I$2001,Orders!$D$2:$D$2001,A2,Orders!$M$2:$M$2001,"West") -> 155358.84 | H2: =RANK(G2,$G$2:$G$61,0) -> 10 | I2: =B2 -> Smartphone Pro
A3: PROD-002 | B3: Wireless Earbuds | C3: Electronics | D3: 1052 | E3: 2600 | F3: =TRUE() -> TRUE | G3: =SUMIFS(Orders!$I$2:$I$2001,Orders!$D$2:$D$2001,A3,Orders!$M$2:$M$2001,"West") -> 105284.4 | H3: =RANK(G3,$G$2:$G$61,0) -> 23 | I3: =B3 -> Wireless Earbuds
A4: PROD-003 | B4: Smart Watch | C4: Electronics | D4: 1665 | E4: 3570 | F4: =TRUE() -> TRUE | G4: =SUMIFS(Orders!$I$2:$I$2001,Orders!$D$2:$D$2001,A4,Orders!$M$2:$M$2001,"West") -> 248025.75 | H4: =RANK(G4,$G$2:$G$61,0) -> 2 | I4: =B4 -> Smart Watch
A5: PROD-004 | B5: Laptop Bag | C5: Electronics | D5: 1559 | E5: 3870 | F5: =TRUE() -> TRUE | G5: =SUMIFS(Orders!$I$2:$I$2001,Orders!$D$2:$D$2001,A5,Orders!$M$2:$M$2001,"West") -> 198124.65 | H5: =RANK(G5,$G$2:$G$61,0) -> 5 | I5: =B5 -> Laptop Bag
A6: PROD-005 | B6: Power Bank | C6: Electronics | D6: 128 | E6: 300 | F6: =TRUE() -> TRUE | G6: =SUMIFS(Orders!$I$2:$I$2001,Orders!$D$2:$D$2001,A6,Orders!$M$2:$M$2001,"West") -> 7449.9 | H6: =RANK(G6,$G$2:$G$61,0) -> 59 | I6: =B6 -> Power Bank
A7: PROD-006 | B7: Bluetooth Speaker | C7: Electronics | D7: 2865 | E7: 3970 | F7: =TRUE() -> TRUE | G7: =SUMIFS(Orders!$I$2:$I$2001,Orders!$D$2:$D$2001,A7,Orders!$M$2:$M$2001,"West") -> 100869.76 | H7: =RANK(G7,$G$2:$G$61,0) -> 28 | I7: =B7 -> Bluetooth Speaker
A8: PROD-007 | B8: USB-C Cable | C8: Electronics | D8: 861 | E8: 1430 | F8: =TRUE() -> TRUE | G8: =SUMIFS(Orders!$I$2:$I$2001,Orders!$D$2:$D$2001,A8,Orders!$M$2:$M$2001,"West") -> 38531.35 | H8: =RANK(G8,$G$2:$G$61,0) -> 48 | I8: =B8 -> USB-C Cable
A9: PROD-008 | B9: Wireless Mouse | C9: Electronics | D9: 1259 | E9: 2660 | F9: =FALSE() -> FALSE | G9: =SUMIFS(Orders!$I$2:$I$2001,Orders!$D$2:$D$2001,A9,Orders!$M$2:$M$2001,"West") -> 7807.1 | H9: =RANK(G9,$G$2:$G$61,0) -> 58 | I9: =B9 -> Wireless Mouse
A10: PROD-009 | B10: Mechanical Keyboard | C10: Electronics | D10: 517 | E10: 1220 | F10: =TRUE() -> TRUE | G10: =SUMIFS(Orders!$I$2:$I$2001,Orders!$D$2:$D$2001,A10,Orders!$M$2:$M$2001,"West") -> 64207.38 | H10: =RANK(G10,$G$2:$G$61,0) -> 44 | I10: =B10 -> Mechanical Keyboard
A11: PROD-010 | B11: Tablet Stand | C11: Electronics | D11: 1149 | E11: 2640 | F11: =TRUE() -> TRUE | G11: =SUMIFS(Orders!$I$2:$I$2001,Orders!$D$2:$D$2001,A11,Orders!$M$2:$M$2001,"West") -> 67393.92 | H11: =RANK(G11,$G$2:$G$61,0) -> 42 | I11: =B11 -> Tablet Stand
A12: PROD-011 | B12: Cotton T-Shirt | C12: Apparel | D12: 1748 | E12: 3450 | F12: =TRUE() -> TRUE | G12: =SUMIFS(Orders!$I$2:$I$2001,Orders!$D$2:$D$2001,A12,Orders!$M$2:$M$2001,"West") -> 145224.3 | H12: =RANK(G12,$G$2:$G$61,0) -> 12 | I12: =B12 -> Cotton T-Shirt
A13: PROD-012 | B13: Denim Jeans | C13: Apparel | D13: 1886 | E13: 3160 | F13: =TRUE() -> TRUE | G13: =SUMIFS(Orders!$I$2:$I$2001,Orders!$D$2:$D$2001,A13,Orders!$M$2:$M$2001,"West") -> 121770.6 | H13: =RANK(G13,$G$2:$G$61,0) -> 16 | I13: =B13 -> Denim Jeans
A14: PROD-013 | B14: Formal Shirt | C14: Apparel | D14: 2611 | E14: 3640 | F14: =TRUE() -> TRUE | G14: =SUMIFS(Orders!$I$2:$I$2001,Orders!$D$2:$D$2001,A14,Orders!$M$2:$M$2001,"West") -> 85543.64 | H14: =RANK(G14,$G$2:$G$61,0) -> 34 | I14: =B14 -> Formal Shirt
A15: PROD-014 | B15: Winter Jacket | C15: Apparel | D15: 2509 | E15: 3620 | F15: =TRUE() -> TRUE | G15: =SUMIFS(Orders!$I$2:$I$2001,Orders!$D$2:$D$2001,A15,Orders!$M$2:$M$2001,"West") -> 95390.62 | H15: =RANK(G15,$G$2:$G$61,0) -> 31 | I15: =B15 -> Winter Jacket
A16: PROD-015 | B16: Sports Shoes | C16: Apparel | D16: 1962 | E16: 2720 | F16: =TRUE() -> TRUE | G16: =SUMIFS(Orders!$I$2:$I$2001,Orders!$D$2:$D$2001,A16,Orders!$M$2:$M$2001,"West") -> 108190.72 | H16: =RANK(G16,$G$2:$G$61,0) -> 22 | I16: =B16 -> Sports Shoes
A17: PROD-016 | B17: Casual Sneakers | C17: Apparel | D17: 396 | E17: 620 | F17: =TRUE() -> TRUE | G17: =SUMIFS(Orders!$I$2:$I$2001,Orders!$D$2:$D$2001,A17,Orders!$M$2:$M$2001,"West") -> 12964.82 | H17: =RANK(G17,$G$2:$G$61,0) -> 56 | I17: =B17 -> Casual Sneakers
A18: PROD-017 | B18: Silk Saree | C18: Apparel | D18: 1075 | E18: 2510 | F18: =FALSE() -> FALSE | G18: =SUMIFS(Orders!$I$2:$I$2001,Orders!$D$2:$D$2001,A18,Orders!$M$2:$M$2001,"West") -> 84699.95 | H18: =RANK(G18,$G$2:$G$61,0) -> 35 | I18: =B18 -> Silk Saree
A19: PROD-018 | B19: Kurta Set | C19: Apparel | D19: 2629 | E19: 3560 | F19: =TRUE() -> TRUE | G19: =SUMIFS(Orders!$I$2:$I$2001,Orders!$D$2:$D$2001,A19,Orders!$M$2:$M$2001,"West") -> 100288.76 | H19: =RANK(G19,$G$2:$G$61,0) -> 29 | I19: =B19 -> Kurta Set
A20: PROD-019 | B20: Track Pants | C20: Apparel | D20: 1173 | E20: 2480 | F20: =TRUE() -> TRUE | G20: =SUMIFS(Orders!$I$2:$I$2001,Orders!$D$2:$D$2001,A20,Orders!$M$2:$M$2001,"West") -> 104993.28 | H20: =RANK(G20,$G$2:$G$61,0) -> 24 | I20: =B20 -> Track Pants
A21: PROD-020 | B21: Woolen Sweater | C21: Apparel | D21: 391 | E21: 820 | F21: =TRUE() -> TRUE | G21: =SUMIFS(Orders!$I$2:$I$2001,Orders!$D$2:$D$2001,A21,Orders!$M$2:$M$2001,"West") -> 9173.34 | H21: =RANK(G21,$G$2:$G$61,0) -> 57 | I21: =B21 -> Woolen Sweater
A22: PROD-021 | B22: Basmati Rice 5kg | C22: Grocery | D22: 1435 | E22: 2760 | F22: =TRUE() -> TRUE | G22: =SUMIFS(Orders!$I$2:$I$2001,Orders!$D$2:$D$2001,A22,Orders!$M$2:$M$2001,"West") -> 90555.6 | H22: =RANK(G22,$G$2:$G$61,0) -> 32 | I22: =B22 -> Basmati Rice 5kg
A23: PROD-022 | B23: Wheat Flour 10kg | C23: Grocery | D23: 1412 | E23: 2270 | F23: =TRUE() -> TRUE | G23: =SUMIFS(Orders!$I$2:$I$2001,Orders!$D$2:$D$2001,A23,Orders!$M$2:$M$2001,"West") -> 66299.89 | H23: =RANK(G23,$G$2:$G$61,0) -> 43 | I23: =B23 -> Wheat Flour 10kg
A24: PROD-023 | B24: Cooking Oil 5L | C24: Grocery | D24: 1182 | E24: 2380 | F24: =TRUE() -> TRUE | G24: =SUMIFS(Orders!$I$2:$I$2001,Orders!$D$2:$D$2001,A24,Orders!$M$2:$M$2001,"West") -> 84480.48 | H24: =RANK(G24,$G$2:$G$61,0) -> 36 | I24: =B24 -> Cooking Oil 5L
A25: PROD-024 | B25: Turmeric Powder 500g | C25: Grocery | D25: 1203 | E25: 2270 | F25: =TRUE() -> TRUE | G25: =SUMIFS(Orders!$I$2:$I$2001,Orders!$D$2:$D$2001,A25,Orders!$M$2:$M$2001,"West") -> 77055.15 | H25: =RANK(G25,$G$2:$G$61,0) -> 38 | I25: =B25 -> Turmeric Powder 500g
A26: PROD-025 | B26: Chili Powder 500g | C26: Grocery | D26: 2911 | E26: 4060 | F26: =TRUE() -> TRUE | G26: =SUMIFS(Orders!$I$2:$I$2001,Orders!$D$2:$D$2001,A26,Orders!$M$2:$M$2001,"West") -> 190994.58 | H26: =RANK(G26,$G$2:$G$61,0) -> 6 | I26: =B26 -> Chili Powder 500g
A27: PROD-026 | B27: Sugar 5kg | C27: Grocery | D27: 2027 | E27: 4070 | F27: =TRUE() -> TRUE | G27: =SUMIFS(Orders!$I$2:$I$2001,Orders!$D$2:$D$2001,A27,Orders!$M$2:$M$2001,"West") -> 179739.34 | H27: =RANK(G27,$G$2:$G$61,0) -> 7 | I27: =B27 -> Sugar 5kg
A28: PROD-027 | B28: Tea Leaves 1kg | C28: Grocery | D28: 2436 | E28: 3780 | F28: =TRUE() -> TRUE | G28: =SUMIFS(Orders!$I$2:$I$2001,Orders!$D$2:$D$2001,A28,Orders!$M$2:$M$2001,"West") -> 39599.28 | H28: =RANK(G28,$G$2:$G$61,0) -> 47 | I28: =B28 -> Tea Leaves 1kg
A29: PROD-028 | B29: Coffee Beans 500g | C29: Grocery | D29: 2214 | E29: 3660 | F29: =FALSE() -> FALSE | G29: =SUMIFS(Orders!$I$2:$I$2001,Orders!$D$2:$D$2001,A29,Orders!$M$2:$M$2001,"West") -> 112574.28 | H29: =RANK(G29,$G$2:$G$61,0) -> 19 | I29: =B29 -> Coffee Beans 500g
A30: PROD-029 | B30: Ghee 1L | C30: Grocery | D30: 1010 | E30: 2210 | F30: =TRUE() -> TRUE | G30: =SUMIFS(Orders!$I$2:$I$2001,Orders!$D$2:$D$2001,A30,Orders!$M$2:$M$2001,"West") -> 118562.08 | H30: =RANK(G30,$G$2:$G$61,0) -> 18 | I30: =B30 -> Ghee 1L
A31: PROD-030 | B31: Salt 1kg | C31: Grocery | D31: 434 | E31: 970 | F31: =TRUE() -> TRUE | G31: =SUMIFS(Orders!$I$2:$I$2001,Orders!$D$2:$D$2001,A31,Orders!$M$2:$M$2001,"West") -> 37405.14 | H31: =RANK(G31,$G$2:$G$61,0) -> 49 | I31: =B31 -> Salt 1kg
A32: PROD-031 | B32: Bed Sheet Set | C32: Home | D32: 2135 | E32: 3730 | F32: =TRUE() -> TRUE | G32: =SUMIFS(Orders!$I$2:$I$2001,Orders!$D$2:$D$2001,A32,Orders!$M$2:$M$2001,"West") -> 102321.36 | H32: =RANK(G32,$G$2:$G$61,0) -> 27 | I32: =B32 -> Bed Sheet Set
A33: PROD-032 | B33: Pillow Cover Pair | C33: Home | D33: 288 | E33: 370 | F33: =TRUE() -> TRUE | G33: =SUMIFS(Orders!$I$2:$I$2001,Orders!$D$2:$D$2001,A33,Orders!$M$2:$M$2001,"West") -> 20402.17 | H33: =RANK(G33,$G$2:$G$61,0) -> 53 | I33: =B33 -> Pillow Cover Pair
A34: PROD-033 | B34: Curtain Set | C34: Home | D34: 1143 | E34: 2030 | F34: =TRUE() -> TRUE | G34: =SUMIFS(Orders!$I$2:$I$2001,Orders!$D$2:$D$2001,A34,Orders!$M$2:$M$2001,"West") -> 137585.28 | H34: =RANK(G34,$G$2:$G$61,0) -> 14 | I34: =B34 -> Curtain Set
A35: PROD-034 | B35: Kitchen Towel Set | C35: Home | D35: 2459 | E35: 5080 | F35: =TRUE() -> TRUE | G35: =SUMIFS(Orders!$I$2:$I$2001,Orders!$D$2:$D$2001,A35,Orders!$M$2:$M$2001,"West") -> 221112.08 | H35: =RANK(G35,$G$2:$G$61,0) -> 4 | I35: =B35 -> Kitchen Towel Set
A36: PROD-035 | B36: Doormat | C36: Home | D36: 464 | E36: 1090 | F36: =TRUE() -> TRUE | G36: =SUMIFS(Orders!$I$2:$I$2001,Orders!$D$2:$D$2001,A36,Orders!$M$2:$M$2001,"West") -> 26929.54 | H36: =RANK(G36,$G$2:$G$61,0) -> 51 | I36: =B36 -> Doormat
A37: PROD-036 | B37: Wall Clock | C37: Home | D37: 1556 | E37: 3250 | F37: =TRUE() -> TRUE | G37: =SUMIFS(Orders!$I$2:$I$2001,Orders!$D$2:$D$2001,A37,Orders!$M$2:$M$2001,"West") -> 88426 | H37: =RANK(G37,$G$2:$G$61,0) -> 33 | I37: =B37 -> Wall Clock
A38: PROD-037 | B38: Table Lamp | C38: Home | D38: 329 | E38: 660 | F38: =TRUE() -> TRUE | G38: =SUMIFS(Orders!$I$2:$I$2001,Orders!$D$2:$D$2001,A38,Orders!$M$2:$M$2001,"West") -> 13841.52 | H38: =RANK(G38,$G$2:$G$61,0) -> 55 | I38: =B38 -> Table Lamp
A39: PROD-038 | B39: Storage Box | C39: Home | D39: 2549 | E39: 5490 | F39: =TRUE() -> TRUE | G39: =SUMIFS(Orders!$I$2:$I$2001,Orders!$D$2:$D$2001,A39,Orders!$M$2:$M$2001,"West") -> 119445.93 | H39: =RANK(G39,$G$2:$G$61,0) -> 17 | I39: =B39 -> Storage Box
A40: PROD-039 | B40: Photo Frame | C40: Home | D40: 1850 | E40: 4610 | F40: =TRUE() -> TRUE | G40: =SUMIFS(Orders!$I$2:$I$2001,Orders!$D$2:$D$2001,A40,Orders!$M$2:$M$2001,"West") -> 177512.66 | H40: =RANK(G40,$G$2:$G$61,0) -> 8 | I40: =B40 -> Photo Frame
...

Sheet Sales_Reps
A1: rep_id | B1: rep_name | C1: region | D1: hire_date | E1: team_lead_id | F1: total_revenue | G1: rank | H1: rep_name_copy
A2: R001 | B2: Rajesh Malhotra | C2: North | D2: 44207 | F2: =SUMIF(Orders!$E$2:$E$2001,A2,Orders!$I$2:$I$2001) -> 789849.6 | G2: =RANK(F2,$F$2:$F$31,0) -> 23 | H2: =B2 -> Rajesh Malhotra
A3: R002 | B3: Sunita Malhotra | C3: North | D3: 44028 | F3: =SUMIF(Orders!$E$2:$E$2001,A3,Orders!$I$2:$I$2001) -> 980063.66 | G3: =RANK(F3,$F$2:$F$31,0) -> 9 | H3: =B3 -> Sunita Malhotra
A4: R003 | B4: Amit Singh | C4: North | D4: 43651 | F4: =SUMIF(Orders!$E$2:$E$2001,A4,Orders!$I$2:$I$2001) -> 986692.91 | G4: =RANK(F4,$F$2:$F$31,0) -> 7 | H4: =B4 -> Amit Singh
A5: R004 | B5: Priya Singh | C5: North | D5: 44907 | F5: =SUMIF(Orders!$E$2:$E$2001,A5,Orders!$I$2:$I$2001) -> 589026.29 | G5: =RANK(F5,$F$2:$F$31,0) -> 29 | H5: =B5 -> Priya Singh
A6: R005 | B6: Vikram Patel | C6: North | D6: 43588 | E6: R001 | F6: =SUMIF(Orders!$E$2:$E$2001,A6,Orders!$I$2:$I$2001) -> 782445.33 | G6: =RANK(F6,$F$2:$F$31,0) -> 24 | H6: =B6 -> Vikram Patel
A7: R006 | B7: Neha Desai | C7: North | D7: 44131 | E7: R001 | F7: =SUMIF(Orders!$E$2:$E$2001,A7,Orders!$I$2:$I$2001) -> 1138648.7 | G7: =RANK(F7,$F$2:$F$31,0) -> 1 | H7: =B7 -> Neha Desai
A8: R007 | B8: Suresh Menon | C8: North | D8: 43493 | E8: R001 | F8: =SUMIF(Orders!$E$2:$E$2001,A8,Orders!$I$2:$I$2001) -> 855749.68 | G8: =RANK(F8,$F$2:$F$31,0) -> 19 | H8: =B8 -> Suresh Menon
A9: R008 | B9: Kavita Patel | C9: North | D9: 44693 | E9: R001 | F9: =SUMIF(Orders!$E$2:$E$2001,A9,Orders!$I$2:$I$2001) -> 861553.33 | G9: =RANK(F9,$F$2:$F$31,0) -> 18 | H9: =B9 -> Kavita Patel
A10: R009 | B10: Manoj Patel | C10: South | D10: 44804 | E10: R002 | F10: =SUMIF(Orders!$E$2:$E$2001,A10,Orders!$I$2:$I$2001) -> 914554.72 | G10: =RANK(F10,$F$2:$F$31,0) -> 12 | H10: =B10 -> Manoj Patel
A11: R010 | B11: Divya Rao | C11: South | D11: 43904 | E11: R002 | F11: =SUMIF(Orders!$E$2:$E$2001,A11,Orders!$I$2:$I$2001) -> 880345.2 | G11: =RANK(F11,$F$2:$F$31,0) -> 17 | H11: =B11 -> Divya Rao
A12: R011 | B12: Anil Verma | C12: South | D12: 44622 | E12: R002 | F12: =SUMIF(Orders!$E$2:$E$2001,A12,Orders!$I$2:$I$2001) -> 735207.76 | G12: =RANK(F12,$F$2:$F$31,0) -> 28 | H12: =B12 -> Anil Verma
A13: R012 | B13: Pooja Nair | C13: South | D13: 44890 | E13: R002 | F13: =SUMIF(Orders!$E$2:$E$2001,A13,Orders!$I$2:$I$2001) -> 901394.32 | G13: =RANK(F13,$F$2:$F$31,0) -> 14 | H13: =B13 -> Pooja Nair
A14: R013 | B14: Sanjay Kapoor | C14: South | D14: 45215 | E14: R002 | F14: =SUMIF(Orders!$E$2:$E$2001,A14,Orders!$I$2:$I$2001) -> 811524.38 | G14: =RANK(F14,$F$2:$F$31,0) -> 22 | H14: =B14 -> Sanjay Kapoor
A15: R014 | B15: Ritu Menon | C15: South | D15: 44469 | E15: R002 | F15: =SUMIF(Orders!$E$2:$E$2001,A15,Orders!$I$2:$I$2001) -> 995713.54 | G15: =RANK(F15,$F$2:$F$31,0) -> 6 | H15: =B15 -> Ritu Menon
A16: R015 | B16: Deepak Shah | C16: South | D16: 45231 | E16: R002 | F16: =SUMIF(Orders!$E$2:$E$2001,A16,Orders!$I$2:$I$2001) -> 1091740.2 | G16: =RANK(F16,$F$2:$F$31,0) -> 3 | H16: =B16 -> Deepak Shah
A17: R016 | B17: Anjali Chopra | C17: South | D17: 43614 | E17: R002 | F17: =SUMIF(Orders!$E$2:$E$2001,A17,Orders!$I$2:$I$2001) -> 814563.71 | G17: =RANK(F17,$F$2:$F$31,0) -> 21 | H17: =B17 -> Anjali Chopra
... A31: R030 | B31: Kiran Bhatt | C31: West | D31: 44506 | E31: R004 | F31: =SUMIF(Orders!$E$2:$E$2001,A31,Orders!$I$2:$I$2001) -> 747624.37 | G31: =RANK(F31,$F$2:$F$31,0) -> 27 | H31: =B31 -> Kiran Bhatt

Sheet Targets
A1: rep_id | B1: Jan-24 | C1: Feb-24 | D1: Mar-24 | E1: Apr-24 | F1: May-24 | G1: Jun-24 | H1: Jul-24 | I1: Aug-24 | J1: Sep-24 | K1: Oct-24 | L1: Nov-24 | M1: Dec-24
A2: R001 | B2: 231324 | C2: 171682 | D2: 234376 | E2: 326967 | F2: 350588 | G2: 385324 | H2: 307980 | I2: 327947 | J2: 181016 | K2: 374039 | L2: 212805 | M2: 405999
A3: R002 | B3: 438126 | C3: 346266 | D3: 329993 | E3: 370744 | F3: 294660 | G3: 341556 | H3: 151934 | I3: 223794 | J3: 438641 | K3: 344308 | L3: 296172 | M3: 304288
A4: R003 | B4: 358703 | C4: 320519 | D4: 327321 | E4: 298753 | F4: 254636 | G4: 351929 | H4: 264723 | I4: 216459 | J4: 391945 | K4: 362426 | L4: 289199 | M4: 301863
A5: R004 | B5: 389594 | C5: 376422 | D5: 324156 | E5: 420255 | F5: 409107 | G5: 269954 | H5: 179097 | I5: 370568 | J5: 387395 | K5: 243454 | L5: 232530 | M5: 201999
A6: R005 | B6: 436862 | C6: 391158 | D6: 340224 | E6: 170548 | F6: 229390 | G6: 349525 | H6: 154683 | I6: 320848 | J6: 354452 | K6: 377180 | L6: 342347 | M6: 183362
A7: R006 | B7: 348734 | C7: 358191 | D7: 250385 | E7: 219657 | F7: 249365 | G7: 435704 | H7: 260892 | I7: 250741 | J7: 358402 | K7: 379858 | L7: 213280 | M7: 224634
A8: R007 | B8: 280057 | C8: 330342 | D8: 336856 | E8: 227425 | F8: 233647 | G8: 307088 | H8: 370724 | I8: 440008 | J8: 406347 | K8: 217357 | L8: 299289 | M8: 214568
A9: R008 | B9: 252886 | C9: 206057 | D9: 318209 | E9: 411230 | F9: 448660 | G9: 171135 | H9: 305339 | I9: 432264 | J9: 294273 | K9: 371409 | L9: 284207 | M9: 437068
A10: R009 | B10: 268752 | C10: 393256 | D10: 310649 | E10: 246237 | F10: 271287 | G10: 314545 | H10: 406506 | I10: 334930 | J10: 348625 | K10: 408928 | L10: 243749 | M10: 418409
A11: R010 | B11: 384734 | C11: 156698 | D11: 283679 | E11: 276085 | F11: 409270 | G11: 285230 | H11: 304233 | I11: 178221 | J11: 284216 | K11: 287373 | L11: 229082 | M11: 298969
A12: R011 | B12: 186029 | C12: 151419 | D12: 253251 | E12: 379757 | F12: 204209 | G12: 179396 | H12: 378008 | I12: 182649 | J12: 267772 | K12: 350352 | L12: 358042 | M12: 359960
A13: R012 | B13: 352158 | C13: 251181 | D13: 321255 | E13: 300863 | F13: 241731 | G13: 393275 | H13: 313561 | I13: 283604 | J13: 429065 | K13: 194420 | L13: 254168 | M13: 389283
... A31: R030 | B31: 151584 | C31: 221679 | D31: 385157 | E31: 290386 | F31: 236041 | G31: 407985 | H31: 184446 | I31: 342894 | J31: 180344 | K31: 292917 | L31: 314858 | M31: 364057

Sheet Q1_Lookups
A1: Q1 - LOOKUP FUNCTIONS (25 marks total)
A2: VLOOKUP · INDEX-MATCH · Two-way lookup · Chain lookup · Approximate lookup · Self-join
A4: Q# | B4: Question | C4: Marks | D4: Hint | E4: Your Answer | F4: Format | H4: Helper steps
A5: Q1.1 | B5: For order ORD-00234, what is the customer_id? | C5: 3 | D5: Simple VLOOKUP on Orders sheet. | E5: =VLOOKUP("ORD-00234",Orders!A:C,3,0) -> CUST-0173 | F5: CUST-####
A6: Q1.2 | B6: For order ORD-00456, what is the product_name? (You will need to look up the product_id first, then find its name in Products.) | C6: 3 | D6: Two-step lookup, or nested VLOOKUP. | E6: =VLOOKUP(H6,Products!A:B,2,0) -> Dumbbells 5kg | F6: Text | H6: =VLOOKUP("ORD-00456",Orders!A:D,4,0) -> PROD-052
A7: Q1.3 | B7: For order ORD-00987, what is the rep_name of the sales rep? Note: the rep_name is in a column that appears to the LEFT of what you might look up first. | C7: 3 | D7: VLOOKUP has directional limits - INDEX/MATCH does not. | E7: =VLOOKUP(H7,Sales_Reps!A:B,2,0) -> Nisha Menon | F7: Text | H7: =VLOOKUP("ORD-00987",Orders!A:E,5,0) -> R022
A8: Q1.4 | B8: From the Targets sheet, what is the target value for rep R012 in the month Mar-24? | C8: 4 | D8: Two-way lookup: row = rep_id, column = month. | E8: =VLOOKUP("R012",Targets!A:M,H8,0) -> 321255 | F8: Whole number | H8: =MATCH("Mar-24",Targets!A1:M1,0) -> 4
A9: Q1.5 | B9: For order ORD-01500, what is the CATEGORY of the product ordered? (Chain: order → product_id → category) | C9: 4 | D9: Multi-hop lookup across sheets. | E9: =VLOOKUP(H9,Products!A:C,3,0) -> Electronics | F9: Text | H9: =VLOOKUP("ORD-01500",Orders!A:D,4,0) -> PROD-004
A10: Q1.6 | B10: For order ORD-00789, which DISCOUNT SLAB does it fall in? Use the slab table below (rows 20-24). Slab breakpoints are the LOWER bound of each range. | C10: 3 | D10: Approximate-match VLOOKUP (sort ascending, TRUE / omit last arg). | E10: =VLOOKUP(H10,B18:C21,2,TRUE()) -> Bronze | F10: Text | H10: =VLOOKUP("ORD-00789",Orders!A:H,8,0) -> 0.9
A11: Q1.7 | B11: For order ORD-01234, in one cell produce the string: "<rep_name> (<sales_region>)" - e.g. "Amit Singh (South)". | C11: 3 | D11: Two lookups joined with & or CONCATENATE. | E11: =I11&" ("&J11&")" -> Sanjay Kapoor (South) | F11: Text | H11: =VLOOKUP("ORD-01234",Orders!A:E,5,0) -> R013 | I11: =VLOOKUP(H11,Sales_Reps!A:C,2,0) -> Sanjay Kapoor | J11: =VLOOKUP(H11,Sales_Reps!A:C,3,0) -> South
A12: Q1.8 | B12: What is the rep_name of the TEAM LEAD for rep R017? (The Sales_Reps sheet has team_lead_id - you need to self-join to find that person's name.) | C12: 2 | D12: Look up the team_lead_id, then look up THAT id's rep_name. | E12: =VLOOKUP(H12,Sales_Reps!A:B,2,0) -> Amit Singh | F12: Text | H12: =VLOOKUP("R017",Sales_Reps!A:E,5,0) -> R003
B15: DISCOUNT SLAB REFERENCE TABLE (use for Q1.6)
B17: Discount % (Lower) | C17: Slab
B18: 0 | C18: Bronze
B19: 5 | C19: Silver
B20: 15 | C20: Gold
B21: 25 | C21: Platinum

Sheet Q2_Cleaning
A1: Q2 - DATA CLEANING & QUALITY DIAGNOSTICS (20 marks total)
A2: Duplicates · Whitespace · Case Inconsistency · Referential Integrity · Discontinued SKUs · Anomaly Patterns
A4: Q# | B4: Question | C4: Marks | D4: Hint | E4: Your Answer | F4: Format
A5: Q2.1 | B5: How many DUPLICATE rows exist in the Orders sheet (i.e., how many order_id values appear more than once)? Count each duplicate as ONE (not the extras). | C5: 3 | D5: COUNTIF > 1, then count. Watch what you're counting - rows or IDs. | E5: =SUM(Orders!T:T) -> 20 | F5: Whole number
A6: Q2.2 | B6: How many customers in the Customers sheet have LEADING or TRAILING whitespace in their customer_name? | C6: 3 | D6: Compare LEN vs LEN(TRIM). Or use SUMPRODUCT with a boolean. | E6: =SUM(Customers!K:K) -> 15 | F6: Whole number
A7: Q2.3 | B7: The Customers sheet has some cities in inconsistent case (e.g., "mumbai", "MUMBAI", "Mumbai"). How many DISTINCT cities exist AFTER standardizing case? | C7: 3 | D7: Combine PROPER/UPPER with a de-dup count. SUMPRODUCT + 1/COUNTIF trick works. | E7: =SUM(Customers!H:H) -> 6 | F7: Whole number
A8: Q2.4 | B8: How many orders reference a customer_id that DOES NOT EXIST in the Customers sheet? (Broken foreign key) | C8: 4 | D8: Use MATCH with ISNA/ISERROR, then count. | E8: =COUNTIF(Orders!U:U,0) -> 30 | F8: Whole number
A9: Q2.5 | B9: How many orders reference a product that is currently DISCONTINUED (is_active = FALSE in the Products sheet)? | C9: 3 | D9: VLOOKUP the is_active flag, then count where FALSE. | E9: =COUNTIF(Orders!Q:Q,FALSE()) -> 174 | F9: Whole number
A10: Q2.6 | B10: Find the "suspicious pattern": how many orders have payment_status = "Cancelled" AND a discount_pct > 20%? (This pattern often indicates promo abuse - a real-world diagnostic query.) | C10: 4 | D10: COUNTIFS with two criteria. | E10: =COUNTIFS(Orders!J:J,"Cancelled",Orders!H:H,">20") -> 58 | F10: Whole number

Sheet Q3_Aggregation
A1: Q3 - CONDITIONAL AGGREGATION (25 marks total)
A2: SUMIFS · COUNTIFS · AVERAGEIFS · Nested IF logic · Multi-sheet aggregation · Top-N logic
A4: Q# | B4: Question | C4: Marks | D4: Hint | E4: Your Answer | F4: Format | H4: Helper steps
A5: Q3.1 | B5: What is the TOTAL REVENUE (sum of final_amount) for orders in Q3 2024 (Jul-Sep) where ship_city is Mumbai? | C5: 4 | D5: SUMIFS with 3 conditions: date >= start, date <= end, city = Mumbai. Beware case issues. | E5: =SUMIFS(Orders!I:I,Orders!B:B,">="&DATE(2024,7,1),Orders!B:B,"<="&DATE(2024,9,30),Orders!K:K,"Mumbai") -> 1217239 | F5: Currency
A6: Q3.2 | B6: How many orders have discount_pct > 15% AND payment_status = "Completed"? | C6: 3 | D6: COUNTIFS with two conditions. | E6: =COUNTIFS(Orders!H:H,">15",Orders!J:J,"Completed") -> 723 | F6: Whole number
A7: Q3.3 | B7: What is the AVERAGE final_amount for orders where the product CATEGORY is "Electronics" AND the customer SEGMENT is "Corporate"? Note: Both fields come from OTHER sheets - you'll need helper columns. | C7: 5 | D7: Helper columns in Orders: VLOOKUP category from Products, VLOOKUP segment from Customers. Then AVERAGEIFS. | E7: =AVERAGEIFS(Orders!I:I,Orders!L:L,"Electronics",Orders!N:N,"Corporate") -> 13981.402 | F7: Currency
A8: Q3.4 | B8: What is the COMBINED REVENUE of the TOP 3 reps by total revenue? (Sum of the 3 highest rep totals.) | C8: 4 | D8: Compute per-rep totals, then use SUMPRODUCT with LARGE, or sort and sum top 3. | E8: =LARGE(Sales_Reps!F:F,1)+LARGE(Sales_Reps!F:F,2)+LARGE(Sales_Reps!F:F,3) -> 3342678.5 | F8: Currency
A9: Q3.5 | B9: For rep R015 in Nov-24: compute the actual revenue and compare to the target (from Targets sheet). Report the PERFORMANCE TIER using: <80% → "Below", 80-120% → "On Track", >120% → "Exceeds". Return only the tier text. | C9: 5 | D9: Nested IF (or IFS): compute actual/target ratio, then classify. | E9: =IF(K9<0.8,"Below",IF(K9<=1.2,"On Track","Exceeds")) -> Below | F9: Text | H9: =SUMIFS(Orders!I:I,Orders!E:E,"R015",Orders!B:B,">="&DATE(2024,11,1),Orders!B:B,"<="&DATE(2024,11,30)) -> 97394.65 | I9: =MATCH("Nov-24",Targets!A1:M1,0) -> 12 | J9: =VLOOKUP("R015",Targets!A:M,I9,0) -> 418857 | K9: =H9/J9 -> 0.23252482
A10: Q3.6 | B10: What is the TOTAL revenue from Corporate segment customers aged between 30 and 40 (both inclusive)? | C10: 4 | D10: Helper columns for age and segment. Then SUMIFS with numeric range. | E10: =SUMIFS(Orders!I:I,Orders!N:N,"Corporate",Orders!O:O,">=30",Orders!O:O,"<=40") -> 982568.4 | F10: Currency

Sheet Q4_Pivot
A1: Q4 - PIVOT TABLES (20 marks total)
A2: 2D Pivots · Filters · % of Row Total · Date Grouping · Calculated Fields · Cross-Sheet Data
A4: Q# | B4: Question | C4: Marks | D4: Hint | E4: Your Answer | F4: Format | H4: Helper steps
A5: Q4.1 | B5: Build a pivot with sales_region as rows and product category as columns, values = SUM of final_amount. What value appears at the intersection of "South" and "Electronics"? | C5: 4 | D5: You need to add category (from Products) and region (from Sales_Reps) as columns to Orders first. Insert PivotTable from combined data. | E5: =SUMIFS(Orders!I:I,Orders!M:M,"South",Orders!L:L,"Electronics") -> 1314107.4 | F5: Currency
A6: Q4.2 | B6: Build a pivot: rows = order month (Jan-24 through Dec-24), columns = sales_rep_id, values = SUM of final_amount. What is the HIGHEST single value in the entire pivot? (One number.) | C6: 4 | D6: After building, use MAX() over the pivot data range, or scan visually. | E6: =MAX(PivotHelper!B2:M31) -> 216421.52 | F6: Currency
A7: Q4.3 | B7: For the North sales_region only: what PERCENTAGE of total revenue comes from the Apparel category? Configure the pivot with Show Values As → % of Row Total. | C7: 4 | D7: Pivot: rows=region, cols=category, values=sum(final_amount), Show Values As = % of Row Total. | E7: =H7/I7 -> 0.1402315 | F7: Percentage | H7: =SUMIFS(Orders!I:I,Orders!M:M,"North",Orders!L:L,"Apparel") -> 979380.97 | I7: =SUMIFS(Orders!I:I,Orders!M:M,"North") -> 6984029.5
A8: Q4.4 | B8: Group order dates by QUARTER in a pivot. What is the total revenue for Q4 2024 (Oct-Dec)? | C8: 4 | D8: PivotTable → Group By → Quarter. Or SUMIFS with date range. | E8: =SUMIFS(Orders!I:I,Orders!B:B,">="&DATE(2024,10,1),Orders!B:B,"<="&DATE(2024,12,31)) -> 6459443 | F8: Currency
A9: Q4.5 | B9: Create a CALCULATED FIELD in the pivot: profit_margin = (unit_price - unit_cost) / unit_price. What is the AVERAGE profit_margin for orders shipped to Delhi? Give as a percentage. | C9: 4 | D9: Add unit_cost via VLOOKUP as helper column. Create pivot calculated field, filter to Delhi. | E9: =AVERAGEIFS(Orders!R:R,Orders!K:K,"Delhi") -> 0.44880873 | F9: Percentage

Sheet Q5_Advanced
A1: Q5 - ADVANCED (10 marks total)
A2: RANK · Running Totals · TEXTJOIN · LARGE + INDEX/MATCH · Multi-condition top-N
A4: Q# | B4: Question | C4: Marks | D4: Hint | E4: Your Answer | F4: Format
A5: Q5.1 | B5: Rank all sales reps by total revenue (highest = rank 1). Who (name) is at RANK #7? | C5: 2 | D5: Per-rep totals, then use RANK.EQ, or sort. Return the rep_name at position 7. | E5: =VLOOKUP(7,Sales_Reps!G:H,2,0) -> Amit Singh | F5: Text
A6: Q5.2 | B6: What is the CUMULATIVE revenue from Jan 2024 through the end of Aug 2024? (Sum of final_amount where order_date <= 31-Aug-2024.) | C6: 2 | D6: SUMIFS with date <=. | E6: =SUMIFS(Orders!I:I,Orders!B:B,"<="&DATE(2024,8,31)) -> 18050690 | F6: Currency
A7: Q5.3 | B7: Among orders where the sales rep is in the WEST region: which product (by name) has the 2nd highest total revenue? | C7: 3 | D7: Helper: sales_region on orders. Filter/pivot to West, sum by product, rank, get #2, VLOOKUP product name. | E7: =VLOOKUP(2,Products!H:I,2,0) -> Smart Watch | F7: Text
A8: Q5.4 | B8: Concatenate the names of the top 5 reps by revenue into a single cell, separated by " | " (space-pipe-space). | C8: 2 | D8: TEXTJOIN with delimiter " | ". Combine with LARGE to pull top 5. | E8: =VLOOKUP(1,Sales_Reps!G:H,2,0)&" | "&VLOOKUP(2,Sales_Reps!G:H,2,0)&" | "&VLOOKUP(3,Sales_Reps!G:H,2,0)&" | "&VLOOKUP(4,Sales_Reps!G:H,2,0)&" | "&VLOOKUP(5,Sales_Reps!G:H,2,0) -> Neha Desai | Shalini Patel | Deepak Shah | Nisha Menon | Arun Iyer | F8: Text
A9: Q5.5 | B9: What is the HIGHEST single order value (final_amount) where ship_city = "Bengaluru" AND the product's category = "Grocery"? | C9: 1 | D9: MAXIFS with a category helper column, or nested MAX(IF()). | E9: =MAX(Orders!V:V) -> 22134 | F9: Currency

Sheet PivotHelper
A1: rep_id | B1: Jan-24 | C1: Feb-24 | D1: Mar-24 | E1: Apr-24 | F1: May-24 | G1: Jun-24 | H1: Jul-24 | I1: Aug-24 | J1: Sep-24 | K1: Oct-24 | L1: Nov-24 | M1: Dec-24
A2: =Sales_Reps!A2 -> R001 | B2: =SUMIFS(Orders!$I$2:$I$2001,Orders!$E$2:$E$2001,$A2,Orders!$B$2:$B$2001,">="&DATE(2024,1,1),Orders!$B$2:$B$2001,"<"&DATE(2024,2,1)) -> 43650.56 | C2: =SUMIFS(Orders!$I$2:$I$2001,Orders!$E$2:$E$2001,$A2,Orders!$B$2:$B$2001,">="&DATE(2024,2,1),Orders!$B$2:$B$2001,"<"&DATE(2024,3,1)) -> 127005.17 | D2: =SUMIFS(Orders!$I$2:$I$2001,Orders!$E$2:$E$2001,$A2,Orders!$B$2:$B$2001,">="&DATE(2024,3,1),Orders!$B$2:$B$2001,"<"&DATE(2024,4,1)) -> 58208.49 | E2: =SUMIFS(Orders!$I$2:$I$2001,Orders!$E$2:$E$2001,$A2,Orders!$B$2:$B$2001,">="&DATE(2024,4,1),Orders!$B$2:$B$2001,"<"&DATE(2024,5,1)) -> 33643.48 | F2: =SUMIFS(Orders!$I$2:$I$2001,Orders!$E$2:$E$2001,$A2,Orders!$B$2:$B$2001,">="&DATE(2024,5,1),Orders!$B$2:$B$2001,"<"&DATE(2024,6,1)) -> 44809.66 | G2: =SUMIFS(Orders!$I$2:$I$2001,Orders!$E$2:$E$2001,$A2,Orders!$B$2:$B$2001,">="&DATE(2024,6,1),Orders!$B$2:$B$2001,"<"&DATE(2024,7,1)) -> 82789.95 | H2: =SUMIFS(Orders!$I$2:$I$2001,Orders!$E$2:$E$2001,$A2,Orders!$B$2:$B$2001,">="&DATE(2024,7,1),Orders!$B$2:$B$2001,"<"&DATE(2024,8,1)) -> 28761.2 | I2: =SUMIFS(Orders!$I$2:$I$2001,Orders!$E$2:$E$2001,$A2,Orders!$B$2:$B$2001,">="&DATE(2024,8,1),Orders!$B$2:$B$2001,"<"&DATE(2024,9,1)) -> 92676.92 | J2: =SUMIFS(Orders!$I$2:$I$2001,Orders!$E$2:$E$2001,$A2,Orders!$B$2:$B$2001,">="&DATE(2024,9,1),Orders!$B$2:$B$2001,"<"&DATE(2024,10,1)) -> 88884.34 | K2: =SUMIFS(Orders!$I$2:$I$2001,Orders!$E$2:$E$2001,$A2,Orders!$B$2:$B$2001,">="&DATE(2024,10,1),Orders!$B$2:$B$2001,"<"&DATE(2024,11,1)) -> 37753.9 | L2: =SUMIFS(Orders!$I$2:$I$2001,Orders!$E$2:$E$2001,$A2,Orders!$B$2:$B$2001,">="&DATE(2024,11,1),Orders!$B$2:$B$2001,"<"&DATE(2024,12,1)) -> 72215.41 | M2: =SUMIFS(Orders!$I$2:$I$2001,Orders!$E$2:$E$2001,$A2,Orders!$B$2:$B$2001,">="&DATE(2024,12,1),Orders!$B$2:$B$2001,"<"&DATE(2025,1,1)) -> 79450.52
A3: =Sales_Reps!A3 -> R002 | B3: =SUMIFS(Orders!$I$2:$I$2001,Orders!$E$2:$E$2001,$A3,Orders!$B$2:$B$2001,">="&DATE(2024,1,1),Orders!$B$2:$B$2001,"<"&DATE(2024,2,1)) -> 51707.32 | C3: =SUMIFS(Orders!$I$2:$I$2001,Orders!$E$2:$E$2001,$A3,Orders!$B$2:$B$2001,">="&DATE(2024,2,1),Orders!$B$2:$B$2001,"<"&DATE(2024,3,1)) -> 125187.78 | D3: =SUMIFS(Orders!$I$2:$I$2001,Orders!$E$2:$E$2001,$A3,Orders!$B$2:$B$2001,">="&DATE(2024,3,1),Orders!$B$2:$B$2001,"<"&DATE(2024,4,1)) -> 53533 | E3: =SUMIFS(Orders!$I$2:$I$2001,Orders!$E$2:$E$2001,$A3,Orders!$B$2:$B$2001,">="&DATE(2024,4,1),Orders!$B$2:$B$2001,"<"&DATE(2024,5,1)) -> 46286.92 | F3: =SUMIFS(Orders!$I$2:$I$2001,Orders!$E$2:$E$2001,$A3,Orders!$B$2:$B$2001,">="&DATE(2024,5,1),Orders!$B$2:$B$2001,"<"&DATE(2024,6,1)) -> 89794.86 | G3: =SUMIFS(Orders!$I$2:$I$2001,Orders!$E$2:$E$2001,$A3,Orders!$B$2:$B$2001,">="&DATE(2024,6,1),Orders!$B$2:$B$2001,"<"&DATE(2024,7,1)) -> 82753.37 | H3: =SUMIFS(Orders!$I$2:$I$2001,Orders!$E$2:$E$2001,$A3,Orders!$B$2:$B$2001,">="&DATE(2024,7,1),Orders!$B$2:$B$2001,"<"&DATE(2024,8,1)) -> 62949.74 | I3: =SUMIFS(Orders!$I$2:$I$2001,Orders!$E$2:$E$2001,$A3,Orders!$B$2:$B$2001,">="&DATE(2024,8,1),Orders!$B$2:$B$2001,"<"&DATE(2024,9,1)) -> 134500.5 | J3: =SUMIFS(Orders!$I$2:$I$2001,Orders!$E$2:$E$2001,$A3,Orders!$B$2:$B$2001,">="&DATE(2024,9,1),Orders!$B$2:$B$2001,"<"&DATE(2024,10,1)) -> 91647.29 | K3: =SUMIFS(Orders!$I$2:$I$2001,Orders!$E$2:$E$2001,$A3,Orders!$B$2:$B$2001,">="&DATE(2024,10,1),Orders!$B$2:$B$2001,"<"&DATE(2024,11,1)) -> 35751.81 | L3: =SUMIFS(Orders!$I$2:$I$2001,Orders!$E$2:$E$2001,$A3,Orders!$B$2:$B$2001,">="&DATE(2024,11,1),Orders!$B$2:$B$2001,"<"&DATE(2024,12,1)) -> 158277.82 | M3: =SUMIFS(Orders!$I$2:$I$2001,Orders!$E$2:$E$2001,$A3,Orders!$B$2:$B$2001,">="&DATE(2024,12,1),Orders!$B$2:$B$2001,"<"&DATE(2025,1,1)) -> 47673.25
A4: =Sales_Reps!A4 -> R003 | B4: =SUMIFS(Orders!$I$2:$I$2001,Orders!$E$2:$E$2001,$A4,Orders!$B$2:$B$2001,">="&DATE(2024,1,1),Orders!$B$2:$B$2001,"<"&DATE(2024,2,1)) -> 54307 | C4: =SUMIFS(Orders!$I$2:$I$2001,Orders!$E$2:$E$2001,$A4,Orders!$B$2:$B$2001,">="&DATE(2024,2,1),Orders!$B$2:$B$2001,"<"&DATE(2024,3,1)) -> 32452 | D4: =SUMIFS(Orders!$I$2:$I$2001,Orders!$E$2:$E$2001,$A4,Orders!$B$2:$B$2001,">="&DATE(2024,3,1),Orders!$B$2:$B$2001,"<"&DATE(2024,4,1)) -> 107489.23 | E4: =SUMIFS(Orders!$I$2:$I$2001,Orders!$E$2:$E$2001,$A4,Orders!$B$2:$B$2001,">="&DATE(2024,4,1),Orders!$B$2:$B$2001,"<"&DATE(2024,5,1)) -> 96349.86 | F4: =SUMIFS(Orders!$I$2:$I$2001,Orders!$E$2:$E$2001,$A4,Orders!$B$2:$B$2001,">="&DATE(2024,5,1),Orders!$B$2:$B$2001,"<"&DATE(2024,6,1)) -> 139257.72 | G4: =SUMIFS(Orders!$I$2:$I$2001,Orders!$E$2:$E$2001,$A4,Orders!$B$2:$B$2001,">="&DATE(2024,6,1),Orders!$B$2:$B$2001,"<"&DATE(2024,7,1)) -> 37966.09 | H4: =SUMIFS(Orders!$I$2:$I$2001,Orders!$E$2:$E$2001,$A4,Orders!$B$2:$B$2001,">="&DATE(2024,7,1),Orders!$B$2:$B$2001,"<"&DATE(2024,8,1)) -> 185921.75 | I4: =SUMIFS(Orders!$I$2:$I$2001,Orders!$E$2:$E$2001,$A4,Orders!$B$2:$B$2001,">="&DATE(2024,8,1),Orders!$B$2:$B$2001,"<"&DATE(2024,9,1)) -> 114656.27 | J4: =SUMIFS(Orders!$I$2:$I$2001,Orders!$E$2:$E$2001,$A4,Orders!$B$2:$B$2001,">="&DATE(2024,9,1),Orders!$B$2:$B$2001,"<"&DATE(2024,10,1)) -> 69896.72 | K4: =SUMIFS(Orders!$I$2:$I$2001,Orders!$E$2:$E$2001,$A4,Orders!$B$2:$B$2001,">="&DATE(2024,10,1),Orders!$B$2:$B$2001,"<"&DATE(2024,11,1)) -> 29309.98 | L4: =SUMIFS(Orders!$I$2:$I$2001,Orders!$E$2:$E$2001,$A4,Orders!$B$2:$B$2001,">="&DATE(2024,11,1),Orders!$B$2:$B$2001,"<"&DATE(2024,12,1)) -> 106760.75 | M4: =SUMIFS(Orders!$I$2:$I$2001,Orders!$E$2:$E$2001,$A4,Orders!$B$2:$B$2001,">="&DATE(2024,12,1),Orders!$B$2:$B$2001,"<"&DATE(2025,1,1)) -> 12325.54
A5: =Sales_Reps!A5 -> R004 | B5: =SUMIFS(Orders!$I$2:$I$2001,Orders!$E$2:$E$2001,$A5,Orders!$B$2:$B$2001,">="&DATE(2024,1,1),Orders!$B$2:$B$2001,"<"&DATE(2024,2,1)) -> 57892.11 | C5: =SUMIFS(Orders!$I$2:$I$2001,Orders!$E$2:$E$2001,$A5,Orders!$B$2:$B$2001,">="&DATE(2024,2,1),Orders!$B$2:$B$2001,"<"&DATE(2024,3,1)) -> 58818.56 | D5: =SUMIFS(Orders!$I$2:$I$2001,Orders!$E$2:$E$2001,$A5,Orders!$B$2:$B$2001,">="&DATE(2024,3,1),Orders!$B$2:$B$2001,"<"&DATE(2024,4,1)) -> 14394.38 | E5: =SUMIFS(Orders!$I$2:$I$2001,Orders!$E$2:$E$2001,$A5,Orders!$B$2:$B$2001,">="&DATE(2024,4,1),Orders!$B$2:$B$2001,"<"&DATE(2024,5,1)) -> 23036.54 | F5: =SUMIFS(Orders!$I$2:$I$2001,Orders!$E$2:$E$2001,$A5,Orders!$B$2:$B$2001,">="&DATE(2024,5,1),Orders!$B$2:$B$2001,"<"&DATE(2024,6,1)) -> 140739.8 | G5: =SUMIFS(Orders!$I$2:$I$2001,Orders!$E$2:$E$2001,$A5,Orders!$B$2:$B$2001,">="&DATE(2024,6,1),Orders!$B$2:$B$2001,"<"&DATE(2024,7,1)) -> 42388.12 | H5: =SUMIFS(Orders!$I$2:$I$2001,Orders!$E$2:$E$2001,$A5,Orders!$B$2:$B$2001,">="&DATE(2024,7,1),Orders!$B$2:$B$2001,"<"&DATE(2024,8,1)) -> 7823.48 | I5: =SUMIFS(Orders!$I$2:$I$2001,Orders!$E$2:$E$2001,$A5,Orders!$B$2:$B$2001,">="&DATE(2024,8,1),Orders!$B$2:$B$2001,"<"&DATE(2024,9,1)) -> 55975.34 | J5: =SUMIFS(Orders!$I$2:$I$2001,Orders!$E$2:$E$2001,$A5,Orders!$B$2:$B$2001,">="&DATE(2024,9,1),Orders!$B$2:$B$2001,"<"&DATE(2024,10,1)) -> 46944.28 | K5: =SUMIFS(Orders!$I$2:$I$2001,Orders!$E$2:$E$2001,$A5,Orders!$B$2:$B$2001,">="&DATE(2024,10,1),Orders!$B$2:$B$2001,"<"&DATE(2024,11,1)) -> 43456.18 | L5: =SUMIFS(Orders!$I$2:$I$2001,Orders!$E$2:$E$2001,$A5,Orders!$B$2:$B$2001,">="&DATE(2024,11,1),Orders!$B$2:$B$2001,"<"&DATE(2024,12,1)) -> 38491.18 | M5: =SUMIFS(Orders!$I$2:$I$2001,Orders!$E$2:$E$2001,$A5,Orders!$B$2:$B$2001,">="&DATE(2024,12,1),Orders!$B$2:$B$2001,"<"&DATE(2025,1,1)) -> 59066.32
A6: =Sales_Reps!A6 -> R005 | B6: =SUMIFS(Orders!$I$2:$I$2001,Orders!$E$2:$E$2001,$A6,Orders!$B$2:$B$2001,">="&DATE(2024,1,1),Orders!$B$2:$B$2001,"<"&DATE(2024,2,1)) -> 70665.51 | C6: =SUMIFS(Orders!$I$2:$I$2001,Orders!$E$2:$E$2001,$A6,Orders!$B$2:$B$2001,">="&DATE(2024,2,1),Orders!$B$2:$B$2001,"<"&DATE(2024,3,1)) -> 57914.81 | D6: =SUMIFS(Orders!$I$2:$I$2001,Orders!$E$2:$E$2001,$A6,Orders!$B$2:$B$2001,">="&DATE(2024,3,1),Orders!$B$2:$B$2001,"<"&DATE(2024,4,1)) -> 85853.43 | E6: =SUMIFS(Orders!$I$2:$I$2001,Orders!$E$2:$E$2001,$A6,Orders!$B$2:$B$2001,">="&DATE(2024,4,1),Orders!$B$2:$B$2001,"<"&DATE(2024,5,1)) -> 46025.56 | F6: =SUMIFS(Orders!$I$2:$I$2001,Orders!$E$2:$E$2001,$A6,Orders!$B$2:$B$2001,">="&DATE(2024,5,1),Orders!$B$2:$B$2001,"<"&DATE(2024,6,1)) -> 67702.82 | G6: =SUMIFS(Orders!$I$2:$I$2001,Orders!$E$2:$E$2001,$A6,Orders!$B$2:$B$2001,">="&DATE(2024,6,1),Orders!$B$2:$B$2001,"<"&DATE(2024,7,1)) -> 113205.32 | H6: =SUMIFS(Orders!$I$2:$I$2001,Orders!$E$2:$E$2001,$A6,Orders!$B$2:$B$2001,">="&DATE(2024,7,1),Orders!$B$2:$B$2001,"<"&DATE(2024,8,1)) -> 20649.35 | I6: =SUMIFS(Orders!$I$2:$I$2001,Orders!$E$2:$E$2001,$A6,Orders!$B$2:$B$2001,">="&DATE(2024,8,1),Orders!$B$2:$B$2001,"<"&DATE(2024,9,1)) -> 15060.28 | J6: =SUMIFS(Orders!$I$2:$I$2001,Orders!$E$2:$E$2001,$A6,Orders!$B$2:$B$2001,">="&DATE(2024,9,1),Orders!$B$2:$B$2001,"<"&DATE(2024,10,1)) -> 81963.69 | K6: =SUMIFS(Orders!$I$2:$I$2001,Orders!$E$2:$E$2001,$A6,Orders!$B$2:$B$2001,">="&DATE(2024,10,1),Orders!$B$2:$B$2001,"<"&DATE(2024,11,1)) -> 99252.77 | L6: =SUMIFS(Orders!$I$2:$I$2001,Orders!$E$2:$E$2001,$A6,Orders!$B$2:$B$2001,">="&DATE(2024,11,1),Orders!$B$2:$B$2001,"<"&DATE(2024,12,1)) -> 55570.99 | M6: =SUMIFS(Orders!$I$2:$I$2001,Orders!$E$2:$E$2001,$A6,Orders!$B$2:$B$2001,">="&DATE(2024,12,1),Orders!$B$2:$B$2001,"<"&DATE(2025,1,1)) -> 68580.8
A7: =Sales_Reps!A7 -> R006 | B7: =SUMIFS(Orders!$I$2:$I$2001,Orders!$E$2:$E$2001,$A7,Orders!$B$2:$B$2001,">="&DATE(2024,1,1),Orders!$B$2:$B$2001,"<"&DATE(2024,2,1)) -> 84968.56 | C7: =SUMIFS(Orders!$I$2:$I$2001,Orders!$E$2:$E$2001,$A7,Orders!$B$2:$B$2001,">="&DATE(2024,2,1),Orders!$B$2:$B$2001,"<"&DATE(2024,3,1)) -> 34581.99 | D7: =SUMIFS(Orders!$I$2:$I$2001,Orders!$E$2:$E$2001,$A7,Orders!$B$2:$B$2001,">="&DATE(2024,3,1),Orders!$B$2:$B$2001,"<"&DATE(2024,4,1)) -> 145435.13 | E7: =SUMIFS(Orders!$I$2:$I$2001,Orders!$E$2:$E$2001,$A7,Orders!$B$2:$B$2001,">="&DATE(2024,4,1),Orders!$B$2:$B$2001,"<"&DATE(2024,5,1)) -> 170939.91 | F7: =SUMIFS(Orders!$I$2:$I$2001,Orders!$E$2:$E$2001,$A7,Orders!$B$2:$B$2001,">="&DATE(2024,5,1),Orders!$B$2:$B$2001,"<"&DATE(2024,6,1)) -> 78322.48 | G7: =SUMIFS(Orders!$I$2:$I$2001,Orders!$E$2:$E$2001,$A7,Orders!$B$2:$B$2001,">="&DATE(2024,6,1),Orders!$B$2:$B$2001,"<"&DATE(2024,7,1)) -> 191251.6 | H7: =SUMIFS(Orders!$I$2:$I$2001,Orders!$E$2:$E$2001,$A7,Orders!$B$2:$B$2001,">="&DATE(2024,7,1),Orders!$B$2:$B$2001,"<"&DATE(2024,8,1)) -> 38479.32 | I7: =SUMIFS(Orders!$I$2:$I$2001,Orders!$E$2:$E$2001,$A7,Orders!$B$2:$B$2001,">="&DATE(2024,8,1),Orders!$B$2:$B$2001,"<"&DATE(2024,9,1)) -> 61857.9 | J7: =SUMIFS(Orders!$I$2:$I$2001,Orders!$E$2:$E$2001,$A7,Orders!$B$2:$B$2001,">="&DATE(2024,9,1),Orders!$B$2:$B$2001,"<"&DATE(2024,10,1)) -> 76627.83 | K7: =SUMIFS(Orders!$I$2:$I$2001,Orders!$E$2:$E$2001,$A7,Orders!$B$2:$B$2001,">="&DATE(2024,10,1),Orders!$B$2:$B$2001,"<"&DATE(2024,11,1)) -> 52942.27 | L7: =SUMIFS(Orders!$I$2:$I$2001,Orders!$E$2:$E$2001,$A7,Orders!$B$2:$B$2001,">="&DATE(2024,11,1),Orders!$B$2:$B$2001,"<"&DATE(2024,12,1)) -> 81500.24 | M7: =SUMIFS(Orders!$I$2:$I$2001,Orders!$E$2:$E$2001,$A7,Orders!$B$2:$B$2001,">="&DATE(2024,12,1),Orders!$B$2:$B$2001,"<"&DATE(2025,1,1)) -> 121741.5
A8: =Sales_Reps!A8 -> R007 | B8: =SUMIFS(Orders!$I$2:$I$2001,Orders!$E$2:$E$2001,$A8,Orders!$B$2:$B$2001,">="&DATE(2024,1,1),Orders!$B$2:$B$2001,"<"&DATE(2024,2,1)) -> 92029.91 | C8: =SUMIFS(Orders!$I$2:$I$2001,Orders!$E$2:$E$2001,$A8,Orders!$B$2:$B$2001,">="&DATE(2024,2,1),Orders!$B$2:$B$2001,"<"&DATE(2024,3,1)) -> 130276.04 | D8: =SUMIFS(Orders!$I$2:$I$2001,Orders!$E$2:$E$2001,$A8,Orders!$B$2:$B$2001,">="&DATE(2024,3,1),Orders!$B$2:$B$2001,"<"&DATE(2024,4,1)) -> 105489.83 | E8: =SUMIFS(Orders!$I$2:$I$2001,Orders!$E$2:$E$2001,$A8,Orders!$B$2:$B$2001,">="&DATE(2024,4,1),Orders!$B$2:$B$2001,"<"&DATE(2024,5,1)) -> 48536.18 | F8: =SUMIFS(Orders!$I$2:$I$2001,Orders!$E$2:$E$2001,$A8,Orders!$B$2:$B$2001,">="&DATE(2024,5,1),Orders!$B$2:$B$2001,"<"&DATE(2024,6,1)) -> 41157.84 | G8: =SUMIFS(Orders!$I$2:$I$2001,Orders!$E$2:$E$2001,$A8,Orders!$B$2:$B$2001,">="&DATE(2024,6,1),Orders!$B$2:$B$2001,"<"&DATE(2024,7,1)) -> 58895.11 | H8: =SUMIFS(Orders!$I$2:$I$2001,Orders!$E$2:$E$2001,$A8,Orders!$B$2:$B$2001,">="&DATE(2024,7,1),Orders!$B$2:$B$2001,"<"&DATE(2024,8,1)) -> 11528.24 | I8: =SUMIFS(Orders!$I$2:$I$2001,Orders!$E$2:$E$2001,$A8,Orders!$B$2:$B$2001,">="&DATE(2024,8,1),Orders!$B$2:$B$2001,"<"&DATE(2024,9,1)) -> 70196.8 | J8: =SUMIFS(Orders!$I$2:$I$2001,Orders!$E$2:$E$2001,$A8,Orders!$B$2:$B$2001,">="&DATE(2024,9,1),Orders!$B$2:$B$2001,"<"&DATE(2024,10,1)) -> 52194.15 | K8: =SUMIFS(Orders!$I$2:$I$2001,Orders!$E$2:$E$2001,$A8,Orders!$B$2:$B$2001,">="&DATE(2024,10,1),Orders!$B$2:$B$2001,"<"&DATE(2024,11,1)) -> 57313.75 | L8: =SUMIFS(Orders!$I$2:$I$2001,Orders!$E$2:$E$2001,$A8,Orders!$B$2:$B$2001,">="&DATE(2024,11,1),Orders!$B$2:$B$2001,"<"&DATE(2024,12,1)) -> 130208.9 | M8: =SUMIFS(Orders!$I$2:$I$2001,Orders!$E$2:$E$2001,$A8,Orders!$B$2:$B$2001,">="&DATE(2024,12,1),Orders!$B$2:$B$2001,"<"&DATE(2025,1,1)) -> 57922.93
A9: =Sales_Reps!A9 -> R008 | B9: =SUMIFS(Orders!$I$2:$I$2001,Orders!$E$2:$E$2001,$A9,Orders!$B$2:$B$2001,">="&DATE(2024,1,1),Orders!$B$2:$B$2001,"<"&DATE(2024,2,1)) -> 61557.02 | C9: =SUMIFS(Orders!$I$2:$I$2001,Orders!$E$2:$E$2001,$A9,Orders!$B$2:$B$2001,">="&DATE(2024,2,1),Orders!$B$2:$B$2001,"<"&DATE(2024,3,1)) -> 23463.3 | D9: =SUMIFS(Orders!$I$2:$I$2001,Orders!$E$2:$E$2001,$A9,Orders!$B$2:$B$2001,">="&DATE(2024,3,1),Orders!$B$2:$B$2001,"<"&DATE(2024,4,1)) -> 164615.05 | E9: =SUMIFS(Orders!$I$2:$I$2001,Orders!$E$2:$E$2001,$A9,Orders!$B$2:$B$2001,">="&DATE(2024,4,1),Orders!$B$2:$B$2001,"<"&DATE(2024,5,1)) -> 12044.56 | F9: =SUMIFS(Orders!$I$2:$I$2001,Orders!$E$2:$E$2001,$A9,Orders!$B$2:$B$2001,">="&DATE(2024,5,1),Orders!$B$2:$B$2001,"<"&DATE(2024,6,1)) -> 67200.57 | G9: =SUMIFS(Orders!$I$2:$I$2001,Orders!$E$2:$E$2001,$A9,Orders!$B$2:$B$2001,">="&DATE(2024,6,1),Orders!$B$2:$B$2001,"<"&DATE(2024,7,1)) -> 82481.44 | H9: =SUMIFS(Orders!$I$2:$I$2001,Orders!$E$2:$E$2001,$A9,Orders!$B$2:$B$2001,">="&DATE(2024,7,1),Orders!$B$2:$B$2001,"<"&DATE(2024,8,1)) -> 75853.47 | I9: =SUMIFS(Orders!$I$2:$I$2001,Orders!$E$2:$E$2001,$A9,Orders!$B$2:$B$2001,">="&DATE(2024,8,1),Orders!$B$2:$B$2001,"<"&DATE(2024,9,1)) -> 61043.44 | J9: =SUMIFS(Orders!$I$2:$I$2001,Orders!$E$2:$E$2001,$A9,Orders!$B$2:$B$2001,">="&DATE(2024,9,1),Orders!$B$2:$B$2001,"<"&DATE(2024,10,1)) -> 49404.64 | K9: =SUMIFS(Orders!$I$2:$I$2001,Orders!$E$2:$E$2001,$A9,Orders!$B$2:$B$2001,">="&DATE(2024,10,1),Orders!$B$2:$B$2001,"<"&DATE(2024,11,1)) -> 26620.46 | L9: =SUMIFS(Orders!$I$2:$I$2001,Orders!$E$2:$E$2001,$A9,Orders!$B$2:$B$2001,">="&DATE(2024,11,1),Orders!$B$2:$B$2001,"<"&DATE(2024,12,1)) -> 64537.26 | M9: =SUMIFS(Orders!$I$2:$I$2001,Orders!$E$2:$E$2001,$A9,Orders!$B$2:$B$2001,">="&DATE(2024,12,1),Orders!$B$2:$B$2001,"<"&DATE(2025,1,1)) -> 172732.12
